console.log("\n--------Try... Catch--------\n")

// Try... Catch is a construction to catch Errors

// What are Errors?
// Error occurs when the code encounters an unexpected condition or behaviour during execution.

// How to invoke an Error?
// - trying to access not existing method or fields

// lets look at example below were were we prepare code that throws an error:

try {
    const emptyArray: string[] = []
    // Now lets try to access not existing element from list:
    console.log("The result of 'emptyArray[1]' is:", emptyArray[1])
    // Now lets try to access not existing element of not existing element from list:
    console.log("The result of 'emptyArray[1][1]' is:", emptyArray[1][1]) // we expect an error here
} catch {
    console.log("An error occurred!")
}

// what if we want to print error?

console.log("\n--------Catch error and print it!--------\n")

// we can add `catch (error)`:

try {
    const emptyArray: string[] = []
    // Now lets try to access not existing element from list:
    console.log("The result of 'emptyArray[1]' is:", emptyArray[1])
    // Now lets try to access not existing element of not existing element from list:
    console.log("The result of 'emptyArray[1][1]' is:", emptyArray[1][1]) // we expect an error here
} catch (error) {
    console.log("An error occurred!")
    console.log(error)
}

// on console ðŸ‘€ you will get:
// The result of 'emptyArray[1]' is: undefined
// An error occurred!
// TypeError: Cannot read properties of undefined (reading '1')
//     at Object.<anonymous> (ts-base\theory\S02\5.exceptions-try-catch.ts:8:70)
//     at Module._compile (node:internal/modules/cjs/loader:1254:14)
//     at Module.m._compile (ts-base\node_modules\ts-node\src\index.ts:1618:23)
//     at Module._extensions..js (node:internal/modules/cjs/loader:1308:10)
//     at Object.require.extensions.<computed> [as .ts] (ts-base\node_modules\ts-node\src\index.ts:1621:12)
//     at Module.load (node:internal/modules/cjs/loader:1117:32)
//     at Function.Module._load (node:internal/modules/cjs/loader:958:12)
//     at Function.executeUserEntryPoint [as runMain] (node:internal/modules/run_main:81:12)
//     at phase4 (ts-base\node_modules\ts-node\src\bin.ts:649:14)
//     at bootstrap (ts-base\node_modules\ts-node\src\bin.ts:95:10)

console.log("\n--------Readable Errors--------\n")

// We can make errors more readable by casting catched error to Error:

try {
    const emptyArray: string[] = []
    // Now lets try to access not existing element from list:
    console.log("The result of 'emptyArray[1]' is:", emptyArray[1])
    // Now lets try to access not existing element of not existing element from list:
    console.log("The result of 'emptyArray[1][1]' is:", emptyArray[1][1])
} catch (error) {
    console.log("An error occurred!")
    let errorTyped = error as Error // we cast error as Error...
    console.log(errorTyped.message) // ...and now we have access to its properties
}

// on console ðŸ‘€ you will get:
// The result of 'emptyArray[1]' is: undefined
// An error occurred!
// Error message: Cannot read properties of undefined (reading '1')

console.log("\n--------Own Errors--------\n")

// We can easily throw an Error using "throw" keyword:

try {
    throw new Error("My custom message for an Error")
} catch (error) {
    console.log("An error occurred!")
    let errorTyped = error as Error // we cast error as Error...
    console.log("Error message:", errorTyped.message) // ...and now we have access to its properties
}

// on console ðŸ‘€ you will get:
// An error occurred!
// Error message: My custom message for an Error

console.log("\n--------Catching only selected types of Errors--------\n")

// each error has a type:
// TypeError
// RangeError
// more You can find here: ðŸ”— https://developer.mozilla.org/en-US/docs/Web/JavaScript/Reference/Global_Objects/Error#error_types

try {
    throw new Error("abc") // ten kawaÅ‚ek kodu sprawia Å¼e dalszy kod nie zostanie wykonany
    const emptyArray: string[] = []
    // Now lets try to access not existing element from list:
    console.log("The result of 'emptyArray[1]' is:", emptyArray[1])
    // Now lets try to access not existing element of not existing element from list:
    console.log("The result of 'emptyArray[1][1]' is:", emptyArray[1][1])
} catch (error) {
    if (error instanceof TypeError) {
        console.log("An error of type TypeError occurred!")
    } else {
        console.log("An unknown error occurred!")
    }
    let errorTyped = error as Error // we cast error as Error...
    console.log(errorTyped.message) // ...and now we have access to its properties
}

// Ignore this line - used to be able to redeclare variables in this project
export {}